#VRML_SIM R2021a utf8
WorldInfo {
  coordinateSystem "NUE"
}
Viewpoint {
  orientation 0.04429145275788728 0.9974860716995935 0.05531549491697183 4.4894798097936235
  position -4.922634526651117 1.325560674858279 -1.283576075709303
}
TexturedBackground {
}
TexturedBackgroundLight {
}
Pioneer3at {
  controller "gym_controller"
  supervisor TRUE
  extensionSlot [
    HingeJoint {
      jointParameters HingeJointParameters {
        anchor 0 0.1 0
        minStop -1
        maxStop 1
      }
      device [
        PositionSensor {
        }
      ]
      endPoint Solid {
        translation 0 0.3999999999999999 1.3877787807814457e-17
        rotation 1 0 0 0
        children [
          DEF POLE_ENDPOINT Solid {
            translation 0 0.26 0
            children [
              DEF BALL_SHAPE Shape {
                appearance CorrodedMetal {
                }
                geometry Sphere {
                  radius 0.1
                  subdivision 3
                }
              }
            ]
            boundingObject USE BALL_SHAPE
            physics Physics {
              density -1
              mass 0.2
            }
          }
          DEF POLE_SHAPE Shape {
            appearance OsbWood {
            }
            geometry Cylinder {
              height 0.5
              radius 0.011
            }
          }
        ]
        boundingObject USE POLE_SHAPE
        physics Physics {
        }
      }
    }
  ]
}
Floor {
  appearance Parquetry {
    type "light strip"
  }
}
