#VRML_SIM R2021a utf8
WorldInfo {
  coordinateSystem "NUE"
}
Viewpoint {
  orientation 0.07668332182985227 0.9942227694431232 0.07510494573585523 4.727392260157678
  position -0.396513422277926 0.13308135571291765 0.06831489081835897
}
E-puck {
  controller "gym_controller"
  supervisor TRUE
  turretSlot [
    HingeJoint {
      jointParameters DEF PENDULUM_PARAMETERS HingeJointParameters {
        position -0.05
        anchor 0 0 -0.01
        minStop -1.6
        maxStop 1.6
      }
      device [
        PositionSensor {
          name "pendulum sensor"
        }
      ]
      endPoint DEF PENDULUM Solid {
        translation 0 0.079900021 -0.013998333
        rotation -1 0 0 1.6208
        children [
          DEF POLE Transform {
            translation 0 0 -0.04
            rotation 1 0 0 1.5707997
            children [
              Shape {
                appearance CorrodedMetal {
                }
                geometry Cylinder {
                  height 0.081
                  radius 0.0015
                }
              }
            ]
          }
          DEF BALL Transform {
            rotation 1 0 0 4.712389
            children [
              Shape {
                appearance CorrodedMetal {
                }
                geometry Sphere {
                  radius 0.0075
                  subdivision 3
                }
              }
            ]
          }
        ]
        boundingObject USE BALL
        physics Physics {
          density -1
          mass 0.05
        }
      }
    }
  ]
}
TexturedBackground {
}
TexturedBackgroundLight {
}
CircleArena {
}
