#VRML_SIM R2021a utf8
WorldInfo {
  coordinateSystem "NUE"
}
Viewpoint {
  orientation 0.06209256440080319 0.9959368221196678 0.06522545356154524 4.659119198006663
  position -0.46134541153049763 0.12478963254613172 -0.026846699581155688
}
Robot {
  translation 0 0.005 0
  rotation 1 0 0 1.5708
  children [
    Shape {
      appearance CorrodedMetal {
      }
      geometry Cylinder {
        radius 0.006
      }
    }
    SliderJoint {
      jointParameters DEF SLIDER_PARAMETERS JointParameters {
        axis 0 1 0
      }
      device [
        PositionSensor {
        }
        LinearMotor {
        }
      ]
      endPoint Solid {
        rotation 1 0 0 -1.5707953071795862
        children [
          HingeJoint {
            jointParameters DEF PENDULUM_PARAMETERS HingeJointParameters {
              anchor 0 0 -0.01
              minStop -1.6
              maxStop 1.6
            }
            device [
              PositionSensor {
                name "pendulum sensor"
              }
            ]
            endPoint DEF PENDULUM Solid {
              translation 0 0.08000000014242674 -0.00999999945047869
              rotation -1 0 0 1.570799999826466
              children [
                DEF POLE Transform {
                  translation 0 0 -0.04
                  rotation 1 0 0 1.5707997
                  children [
                    Shape {
                      appearance CorrodedMetal {
                      }
                      geometry Cylinder {
                        height 0.081
                        radius 0.0015
                      }
                    }
                  ]
                }
                DEF BALL Transform {
                  rotation 1 0 0 4.712389
                  children [
                    Shape {
                      appearance CorrodedMetal {
                        colorOverride 0.8 0 0
                      }
                      geometry Sphere {
                        radius 0.0075
                        subdivision 3
                      }
                    }
                  ]
                }
              ]
              boundingObject USE BALL
              physics Physics {
                density -1
                mass 0.01
              }
            }
          }
        ]
      }
    }
  ]
  controller "gym_controller"
  supervisor TRUE
}
TexturedBackground {
}
TexturedBackgroundLight {
}
CircleArena {
}
